<mujoco model="go1">
  <!--
    Unitree Go1 — MuJoCo model
    Joint physics matched to MuJoCo Menagerie (google-deepmind/mujoco_menagerie).
    Joint axis convention matches cadenza.locomotion.robot_spec FK formula:
      thigh/calf: axis="0 -1 0"  so Ry(-q) matches spec's Ry(-q_thigh)
      hip FL/RL:  axis="1  0 0"  (hs=+1)
      hip FR/RR:  axis="-1 0 0"  (hs=-1)
    All ref="0". Stand pose qpos=(0, 0.9, -1.8) per leg gives foot at ~-0.265m from CoM.
    Physics: thigh=calf=0.213m | max_torque=33.5Nm | total_mass=12kg

    Critical joint settings (from Menagerie — without these the robot oscillates and collapses):
      damping=2.0 (thigh/knee) — passive resistance that kills PD oscillations
      damping=1.0 (hip)        — less damping on lateral joints
      frictionloss=0.2         — static friction to hold joint positions
      armature=0.01            — rotor inertia for smooth dynamics
  -->

  <compiler angle="radian" autolimits="true"/>
  <option gravity="0 0 -9.81" timestep="0.002" iterations="50" tolerance="1e-10"
          cone="elliptic" impratio="100"/>

  <default>
    <!-- Thigh/calf joints: high damping for stable PD control -->
    <joint damping="2.0" frictionloss="0.2" armature="0.01"/>
    <geom contype="1" conaffinity="1" condim="3"
          friction="0.6 0.02 0.001" solref="0.005 1" solimp="0.98 0.99 0.001"/>
    <position kp="300" ctrlrange="-3.14 3.14" forcelimited="true" forcerange="-33.5 33.5"/>

    <!-- Hip joints: less damping (lateral motion needs to be responsive) -->
    <default class="hip_joint">
      <joint damping="1.0" frictionloss="0.2" armature="0.01"/>
    </default>

    <!-- Foot contact: high friction, 6-DOF contact for torsional grip -->
    <default class="foot">
      <geom condim="6" friction="0.8 0.02 0.01"
            solimp="0.015 1 0.023" solref="0.005 1"/>
    </default>
  </default>

  <asset>
    <!-- Outdoor sky -->
    <texture name="sky" type="skybox" builtin="gradient"
             rgb1="0.45 0.60 0.85" rgb2="0.75 0.85 0.95"
             width="512" height="512" mark="random" markrgb="1 1 1"
             random="0.01"/>
    <!-- Concrete ground -->
    <texture name="ground_tex" type="2d" builtin="flat"
             rgb1="0.72 0.70 0.66" rgb2="0.68 0.66 0.62"
             width="512" height="512" mark="random" markrgb="0.65 0.63 0.60"
             random="0.05"/>
    <material name="floor_mat" texture="ground_tex" texrepeat="12 12"
              texuniform="true" reflectance="0.02" rgba="0.75 0.73 0.70 1"/>
    <material name="body_mat"   rgba="0.15 0.15 0.18 1" reflectance="0.05"/>
    <material name="leg_mat"    rgba="0.12 0.12 0.15 1" reflectance="0.03"/>
  </asset>

  <worldbody>
    <light name="sun"  pos="5 3 12"  dir="-0.3 -0.2 -1" diffuse="1.2 1.15 1.0"
           specular="0.5 0.5 0.4" castshadow="true"/>
    <light name="ambient" pos="0 0 10" dir="0 0 -1" diffuse="0.35 0.38 0.45"
           specular="0 0 0" castshadow="false"/>
    <light name="fill" pos="-5 -3 6" dir="0.3 0.2 -1" diffuse="0.25 0.25 0.30"
           castshadow="false"/>

    <!-- Ground — concrete slab -->
    <geom name="floor" type="plane" size="30 30 0.1" material="floor_mat"
          condim="6" friction="0.8 0.02 0.01"/>

    <!-- Forward direction arrow on ground (green = forward, points -x) -->
    <geom name="fwd_arrow_shaft" type="box" size="0.4 0.02 0.003" pos="-0.6 0 0.003"
          rgba="0.1 0.85 0.3 0.8" contype="0" conaffinity="0"/>
    <geom name="fwd_arrow_head" type="box" size="0.06 0.06 0.003" pos="-1.05 0 0.003"
          euler="0 0 0.785" rgba="0.1 0.85 0.3 0.8" contype="0" conaffinity="0"/>


    <!-- ══ Robot trunk ═══════════════════════════════════════════════════ -->
    <body name="trunk" pos="0 0 0.27">
      <freejoint name="root"/>
      <geom name="trunk" type="box" size="0.1881 0.0475 0.048"
            mass="9.041" material="body_mat"/>
      <site name="imu" pos="0 0 0" size="0.005"/>
      <!-- Head marker — bright green sphere at front (-x end) so "forward" is obvious -->
      <geom name="head_marker" type="sphere" size="0.03" pos="-0.22 0 0.04"
            rgba="0.1 0.95 0.3 1" contype="0" conaffinity="0" mass="0.001"/>

      <!-- ── FL leg ──────────────────────────────────────────────────── -->
      <body name="FL_hip" pos="0.1881 0.0472 0">
        <joint name="FL_hip_joint" type="hinge" axis="1 0 0"
               range="-0.863 0.863" class="hip_joint"/>
        <geom type="capsule" size="0.044 0.020" pos="0 0.040 0"
              euler="1.5708 0 0" mass="0.591" material="body_mat"/>
        <body name="FL_thigh" pos="0 0.0838 0">
          <joint name="FL_thigh_joint" type="hinge" axis="0 -1 0"
                 range="-0.686 4.501"/>
          <geom type="capsule" size="0.025" fromto="0 0 0 0 0 -0.213"
                mass="0.921" material="leg_mat" rgba="0.30 0.55 0.90 1"/>
          <body name="FL_calf" pos="0 0 -0.213">
            <joint name="FL_calf_joint" type="hinge" axis="0 -1 0"
                   range="-2.818 -0.888"/>
            <geom type="capsule" size="0.019" fromto="0 0 0 0 0 -0.213"
                  mass="0.135" material="leg_mat"/>
            <body name="FL_foot" pos="0 0 -0.213">
              <geom name="FL_foot_geom" type="sphere" size="0.0165"
                    mass="0.06" rgba="0.30 0.55 0.90 1" class="foot"/>
            </body>
          </body>
        </body>
      </body>

      <!-- ── FR leg ──────────────────────────────────────────────────── -->
      <body name="FR_hip" pos="0.1881 -0.0472 0">
        <joint name="FR_hip_joint" type="hinge" axis="-1 0 0"
               range="-0.863 0.863" class="hip_joint"/>
        <geom type="capsule" size="0.044 0.020" pos="0 -0.040 0"
              euler="1.5708 0 0" mass="0.591" material="body_mat"/>
        <body name="FR_thigh" pos="0 -0.0838 0">
          <joint name="FR_thigh_joint" type="hinge" axis="0 -1 0"
                 range="-0.686 4.501"/>
          <geom type="capsule" size="0.025" fromto="0 0 0 0 0 -0.213"
                mass="0.921" material="leg_mat" rgba="0.90 0.33 0.33 1"/>
          <body name="FR_calf" pos="0 0 -0.213">
            <joint name="FR_calf_joint" type="hinge" axis="0 -1 0"
                   range="-2.818 -0.888"/>
            <geom type="capsule" size="0.019" fromto="0 0 0 0 0 -0.213"
                  mass="0.135" material="leg_mat"/>
            <body name="FR_foot" pos="0 0 -0.213">
              <geom name="FR_foot_geom" type="sphere" size="0.0165"
                    mass="0.06" rgba="0.90 0.33 0.33 1" class="foot"/>
            </body>
          </body>
        </body>
      </body>

      <!-- ── RL leg ──────────────────────────────────────────────────── -->
      <body name="RL_hip" pos="-0.1881 0.0472 0">
        <joint name="RL_hip_joint" type="hinge" axis="1 0 0"
               range="-0.863 0.863" class="hip_joint"/>
        <geom type="capsule" size="0.044 0.020" pos="0 0.040 0"
              euler="1.5708 0 0" mass="0.591" material="body_mat"/>
        <body name="RL_thigh" pos="0 0.0838 0">
          <joint name="RL_thigh_joint" type="hinge" axis="0 -1 0"
                 range="-0.686 4.501"/>
          <geom type="capsule" size="0.025" fromto="0 0 0 0 0 -0.213"
                mass="0.921" material="leg_mat" rgba="0.30 0.90 0.75 1"/>
          <body name="RL_calf" pos="0 0 -0.213">
            <joint name="RL_calf_joint" type="hinge" axis="0 -1 0"
                   range="-2.818 -0.888"/>
            <geom type="capsule" size="0.019" fromto="0 0 0 0 0 -0.213"
                  mass="0.135" material="leg_mat"/>
            <body name="RL_foot" pos="0 0 -0.213">
              <geom name="RL_foot_geom" type="sphere" size="0.0165"
                    mass="0.06" rgba="0.30 0.90 0.75 1" class="foot"/>
            </body>
          </body>
        </body>
      </body>

      <!-- ── RR leg ──────────────────────────────────────────────────── -->
      <body name="RR_hip" pos="-0.1881 -0.0472 0">
        <joint name="RR_hip_joint" type="hinge" axis="-1 0 0"
               range="-0.863 0.863" class="hip_joint"/>
        <geom type="capsule" size="0.044 0.020" pos="0 -0.040 0"
              euler="1.5708 0 0" mass="0.591" material="body_mat"/>
        <body name="RR_thigh" pos="0 -0.0838 0">
          <joint name="RR_thigh_joint" type="hinge" axis="0 -1 0"
                 range="-0.686 4.501"/>
          <geom type="capsule" size="0.025" fromto="0 0 0 0 0 -0.213"
                mass="0.921" material="leg_mat" rgba="0.90 0.65 0.30 1"/>
          <body name="RR_calf" pos="0 0 -0.213">
            <joint name="RR_calf_joint" type="hinge" axis="0 -1 0"
                   range="-2.818 -0.888"/>
            <geom type="capsule" size="0.019" fromto="0 0 0 0 0 -0.213"
                  mass="0.135" material="leg_mat"/>
            <body name="RR_foot" pos="0 0 -0.213">
              <geom name="RR_foot_geom" type="sphere" size="0.0165"
                    mass="0.06" rgba="0.90 0.65 0.30 1" class="foot"/>
            </body>
          </body>
        </body>
      </body>

    </body><!-- /trunk -->
  </worldbody>

  <actuator>
    <!-- Position actuators: ctrl = target angle, MuJoCo applies PD internally.
         forcerange = torque limits per URDF. kp set in default. -->
    <position name="FL_hip"   joint="FL_hip_joint"   ctrlrange="-0.80 0.80"   forcelimited="true" forcerange="-23.7 23.7"/>
    <position name="FL_thigh" joint="FL_thigh_joint" ctrlrange="-0.50 2.50"   forcelimited="true" forcerange="-23.7 23.7"/>
    <position name="FL_calf"  joint="FL_calf_joint"  ctrlrange="-2.75 -0.60"  forcelimited="true" forcerange="-35.55 35.55"/>
    <position name="FR_hip"   joint="FR_hip_joint"   ctrlrange="-0.80 0.80"   forcelimited="true" forcerange="-23.7 23.7"/>
    <position name="FR_thigh" joint="FR_thigh_joint" ctrlrange="-0.50 2.50"   forcelimited="true" forcerange="-23.7 23.7"/>
    <position name="FR_calf"  joint="FR_calf_joint"  ctrlrange="-2.75 -0.60"  forcelimited="true" forcerange="-35.55 35.55"/>
    <position name="RL_hip"   joint="RL_hip_joint"   ctrlrange="-0.80 0.80"   forcelimited="true" forcerange="-23.7 23.7"/>
    <position name="RL_thigh" joint="RL_thigh_joint" ctrlrange="-0.50 2.50"   forcelimited="true" forcerange="-23.7 23.7"/>
    <position name="RL_calf"  joint="RL_calf_joint"  ctrlrange="-2.75 -0.60"  forcelimited="true" forcerange="-35.55 35.55"/>
    <position name="RR_hip"   joint="RR_hip_joint"   ctrlrange="-0.80 0.80"   forcelimited="true" forcerange="-23.7 23.7"/>
    <position name="RR_thigh" joint="RR_thigh_joint" ctrlrange="-0.50 2.50"   forcelimited="true" forcerange="-23.7 23.7"/>
    <position name="RR_calf"  joint="RR_calf_joint"  ctrlrange="-2.75 -0.60"  forcelimited="true" forcerange="-35.55 35.55"/>
  </actuator>

  <keyframe>
    <key name="home" qpos="0 0 0.27 1 0 0 0
                           0 0.9 -1.8  0 0.9 -1.8
                           0 0.9 -1.8  0 0.9 -1.8"/>
  </keyframe>

</mujoco>
